Workbook

Sheet Протокол
A1: МИНИСТЕРСТВО НАУКИ И ВЫСШЕГО ОБРАЗОВАНИЯ РОССИЙСКОЙ ФЕДЕРАЦИИ Федеральное государственное бюджетное образовательное учреждение высшего образования «Тамбовский государственный технический университет»
I3: УТВЕРЖДАЮ:
I4: Проректор по научной работе
I5: Д.Ю. Муромцев
I6: « » 20 г.
A8: ПРОТОКОЛ № 1
A9: заседания экзаменационной комиссии по приему кандидатского экзамена
A10: от « » 20 г.
A12: =VLOOKUP(C29,БД!A:K,3,0) -> Состав комиссии (утверждён приказом ректора университета № 1/3-08 от 12 января 2026 г.)
A13: Председатель комиссии:
A14: =VLOOKUP(C29,БД!A:J,4,0) -> Медведев Н.В., доктор философских наук, профессор, профессор кафедры «История и философия» ФГБОУ ВО ТГУ им. Г.Р. Державина
A15: (фамилия, инициалы, ученая степень, ученое звание, должность)
A16: Члены комиссии:
A17: =VLOOKUP(C29,БД!A:J,6,0) -> Вязинкин А.Ю., кандидат философских наук, доцент, доцент кафедры «История и философия», заместитель председателя комиссии
A18: (фамилия, инициалы, ученая степень, ученое звание, должность)
A19: =VLOOKUP(C29,БД!A:J,8,0) -> Кирякин А. В., кандидат философских наук, доцент кафедры «История и философия»
A20: (фамилия, инициалы, ученая степень, ученое звание, должность)
A22: Прием кандидатского экзамена по научной специальности
A23: =VLOOKUP(Протокол!$C$29,БД!A:K,11,0) -> 4.3.1 Технологии, машины и оборудование для агропромышленного комплекса
A24: (шифр и наименование научной специальности, отрасль науки)
A26: по дисциплине | D26: =VLOOKUP(C29,БД!A:J,2,0) -> История и философия науки
D27: (наименование дисциплины)
A29: СЛУШАЛИ | C29: АГАПОНОВА ДМИТРИЯ АНАТОЛЬЕВИЧА
C30: (фамилия, имя, отчество экзаменуемого лица)
A31: На экзамене были заданы следующие вопросы:
A39: ПОСТАНОВИЛИ: | D39: =VLOOKUP($C$29,БД!A:J,10,0) -> Агапонов Дмитрий Анатольевич | H39: сдал(а) экзамен с оценкой
D40: (фамилия, имя, отчество)
A42: Председатель комиссии | I42: =VLOOKUP(C29,БД!A:J,5,0) -> / Н.В. Медведев /
E43: (подпись) | I43: (фамилия, инициалы)
A45: Член комиссии | I45: =VLOOKUP(C29,БД!A:J,7,0) -> / А.Ю. Вязинкин /
E46: (подпись) | I46: (фамилия, инициалы)
I47: =VLOOKUP(C29,БД!A:J,9,0) -> / А.В. Кирякин /
E48: (подпись) | I48: (фамилия, инициалы)

Sheet БД
A1: СЛУШАЛИ | B1: Прием кандидатского экзамена по дисциплине | C1: Направление | D1: Председатель комиссии: | E1: ФИО | F1: Члены комиссии №1: | G1: ФИО | H1: Члены комиссии №2: | I1: ФИО | J1: ПОСТАНОВИЛИ | K1: НАПРАВЛЕНИЕ
A2: АГАПОНОВА ДМИТРИЯ АНАТОЛЬЕВИЧА | B2: История и философия науки | C2: Состав комиссии (утверждён приказом ректора университета № 1/3-08 от 12 января 2026 г.) | D2: Медведев Н.В., доктор философских наук, профессор, профессор кафедры «История и философия» ФГБОУ ВО ТГУ им. Г.Р. Державина | E2: / Н.В. Медведев / | F2: Вязинкин А.Ю., кандидат философских наук, доцент, доцент кафедры «История и философия», заместитель председателя комиссии | G2: / А.Ю. Вязинкин / | H2: Кирякин А. В., кандидат философских наук, доцент кафедры «История и философия» | I2: / А.В. Кирякин / | J2: Агапонов Дмитрий Анатольевич | K2: 4.3.1 Технологии, машины и оборудование для агропромышленного комплекса
A3: АЛЬ СУДАНИ ЗАЙД АЛИ ХУССЕЙН | B3: Информатика и информационные процессы | C3: Состав комиссии (утверждён приказом ректора университета № 1/3-08 от 12 января 2026 г.) | D3: Громов Ю.Ю., доктор технических наук, профессор, директор института автоматики и информационных технологий | E3: / Ю.Ю. Громов / | F3: Тютюнник В.М., доктор технических наук, профессор, профессор кафедры «Конструирование радиоэлектронных и микропроцессорных систем» | G3: / В.М. Тютюнник / | H3: Минин Ю.В., кандидат технических наук, доцент, доцент кафедры «Информационные системы и защита информации» | I3: / Ю.В. Минин / | J3: Аль Судани Зайд Али Хуссейн | K3: 2.3.8. Информатика и информационные процессы (технические науки)
A4: АНТОНОВА ЕВГЕНИЯ АНДРЕЕВИЧА | B4: Радиотехника, в том числе системы и устройства телевидения | C4: Состав комиссии (утверждён приказом ректора университета № 1/3-08 от 12 января 2026 г.) | D4: Пудовкин А.П., доктор технических наук, профессор, зав. кафедрой «Радиотехника» | E4: / А.П. Пудовкин / | F4: Данилов С.Н., доктор технических наук, профессор, профессор кафедры «Радиотехника» | G4: / С.Н. Данилов / | H4: Иванов А.В., доктор технических наук, профессор, профессор кафедры «Радиотехника» | I4: / А.В. Иванов / | J4: Антонов Евгений Андреевич | K4: 2.2.13. Радиотехника, в том числе системы и устройства телевидения (технические науки)
A5: ЭЛЬБИЛТАДЖИ МАХМУД ХАТИМ САИД АХМЕД АБДИЛ ХАЛИМ | B5: Процессы и аппараты химических технологий | C5: Состав комиссии (утверждён приказом ректора университета № 1/3-08 от 12 января 2026 г.) | D5: Гатапова Н.Ц., доктор технических наук, профессор, зав. кафедрой «Технологические процессы, аппараты и техносферная безопасность» | E5: / Н.Ц. Гатапова / | F5: Туголуков Е.Н., доктор технических наук, профессор, профессор кафедры «Техника и технологии производства нанопродуктов» | G5: / Е.Н. Туголуков / | H5: Пахомов А.Н., доктор технических наук, доцент, доцент кафедры «Технологические процессы, аппараты и техносферная безопасность» | I5: / А.Н. Пахомов / | J5: Эльбилтаджи Махмуд Хатим Саид Ахмед Абдил Халим | K5: 2.6.13. Процессы и аппараты химических технологий (технические науки)
A6: ВОРОНКОВА РОМАНА ВЯЧЕСЛАВОВИЧА | B6: Автоматизация и управление технологическими процессами и производствами | C6: Состав комиссии (утверждён приказом ректора университета № 1/3-08 от 12 января 2026 г.) | D6: Матвейкин В.Г., доктор технических наук, профессор, зав. кафедрой «Информационные процессы и управление» | E6: / В.Г. Матвейкин / | F6: Дмитриевский Б.С., доктор технических наук, профессор, профессор кафедры «Информационные процессы и управление» | G6: / Б.С. Дмитриевский / | H6: Третьяков А.А., кандидат технических наук, доцент, доцент кафедры «Информационные процессы и управление» | I6: / А.А. Третьяков / | J6: Воронков Роман Вячеславович | K6: 2.3.3. Автоматизация и управление технологическими процессами и производствами (технические науки)
A7: ГРИГОРЬЕВА АНДРЕЯ АЛЕКСЕЕВИЧА | B7: Теоретико-исторические правовые науки | C7: Состав комиссии (утверждён приказом ректора университета № 1/3-08 от 12 января 2026 г.) | D7: Працко Г.С., доктор юридических наук, профессор, профессор кафедры «Теория и история государства и права» | E7: / Г.С. Працко / | F7: Марченко А.Н., кандидат юридических наук, доцент, доцент кафедры «Гражданское право и процесс» | G7: / А.Н. Марченко / | H7: Пугина О.А., кандидат юридических наук, доцент, доцент кафедры «Теория и история государства и права» | I7: / О.А. Пугина / | J7: Григорьев Андрей Алексеевич | K7: 5.1.1. Теоретико-исторические правовые науки (юридические науки)
A8: ДОЛГОВА ЕГОРА ПАВЛОВИЧА | B8: Приборы, системы и изделия медицинского назначения | C8: Состав комиссии (утверждён приказом ректора университета № 1/3-08 от 12 января 2026 г.) | D8: Фролов С.В., доктор технических наук, профессор, зав. кафедрой «Биомедицинская техника» | E8: / С.В. Фролов / | F8: Проскурин С.Г., доктор технических наук, доцент, профессор кафедры «Биомедицинская техника» | G8: / С.Г. Проскурин / | H8: Дубровин В.В., кандидат технических наук, доцент, доцент кафедры «Биомедицинская техника» | I8: / В.В. Дубровин / | J8: Долгов Егор Павлович | K8: 2.2.12. Приборы, системы и изделия медицинского назначения (технические науки)
A9: ЗВЕРЕВА МИХАИЛА ВАСИЛЬЕВИЧА | B9: Методы и приборы контроля и диагностики материалов, изделий, веществ и природной среды | C9: Состав комиссии (утверждён приказом ректора университета № 104/4-08 от 10 июня 2024 г.) | D9: Балабанов П.В., доктор технических наук, доцент, зав. кафедрой «Мехатроника и технологические измерения» | E9: / П.В. Балабанов / | F9: Дивин А.Г., доктор технических наук, профессор, профессор кафедры «Мехатроника и технологические измерения» | G9: / А.Г. Дивин / | H9: Пономарев С.В., доктор технических наук, профессор, профессор кафедры «Мехатроника и технологические измерения» | I9: / С.В. Пономарев / | J9: Зверев Михаил Васильевич | K9: 2.2.8. Методы и приборы контроля и диагностики материалов, изделий, веществ и природной среды (технические науки)
A10: КОНЕВА АНДРЕЯ ЮРЬЕВИЧА | B10: Технологии, машины и оборудование для агропромышленного комплекса | C10: Состав комиссии (утверждён приказом ректора университета № 104/4-08 от 10 июня 2024 г.) | D10: Ведищев С.М., доктор технических наук, профессор, зав. кафедрой «Агроинженерия» | E10: / С.М. Ведищев / | F10: Прохоров А.В., кандидат технических наук, доцент, доцент кафедры «Агроинженерия» | G10: / А.В. Прохоров / | H10: Брусенков А.В., кандидат технических наук, доцент, доцент кафедры «Агроинженерия» | I10: / А.В. Брусенков / | J10: Конев Андрей Юрьевич | K10: 4.3.1. Технологии, машины и оборудование для агропромышленного комплекса (технические науки)
A11: КОНЬКОВА ИЛЬЮ АЛЕКСЕЕВИЧА | B11: Теоретико-исторические правовые науки | C11: Состав комиссии (утверждён приказом ректора университета № 104/4-08 от 10 июня 2024 г.) | D11: Працко Г.С., доктор юридических наук, профессор, профессор кафедры «Теория и история государства и права» | E11: / Г.С. Працко / | F11: Марченко А.Н., кандидат юридических наук, доцент, доцент кафедры «Гражданское право и процесс» | G11: / А.Н. Марченко / | H11: Пугина О.А., кандидат юридических наук, доцент, доцент кафедры «Теория и история государства и права» | I11: / О.А. Пугина / | J11: Коньков Илья Алексеевич | K11: 5.1.1. Теоретико-исторические правовые науки (юридические науки)
A12: КРЫЛОВА АЛЕКСЕЯ ВИКТОРОВИЧА | B12: Технология электрохимических процессов и защита от коррозии | C12: Состав комиссии (утверждён приказом ректора университета № 104/4-08 от 10 июня 2024 г.) | D12: Лазарев С.И., доктор технических наук, профессор, директор научно-образовательного центра в области безотходных и малоотходных технологий | E12: / С.И. Лазарев / | F12: Абоносимов О.А., доктор технических наук, доцент, научный сотрудник научно-образовательного центра в области безотходных и малоотходных технологий | G12: / О.А. Абоносимов / | H12: Зарапина И.В., кандидат химических наук, доцент, доцент кафедры «Химия и химические технологии» | I12: / И.В. Зарапина / | J12: Крылов Алексей Викторович | K12: 2.6.9. Технология электрохимических процессов и защита от коррозии (технические науки)
A13: ЛИШНИХ МИХАИЛА АЛЕКСЕЕВИЧА | B13: Нанотехнологии и наноматериалы | C13: Состав комиссии (утверждён приказом ректора университета № 104/4-08 от 10 июня 2024 г.) | D13: Ткачев А.Г., доктор технических наук, профессор, зав. кафедрой «Техника и технологии производства нанопродуктов» | E13: / А.Г. Ткачев / | F13: Туголуков Е.Н., доктор технических наук, профессор, профессор кафедры «Техника и технологии производства нанопродуктов» | G13: / Е.Н. Туголуков / | H13: Буракова Е.А, доктор технических наук, доцент, доцент кафедры «Техника и технологии производства нанопродуктов» | I13: / Е.А Буракова / | J13: Лишних Михаил Алексеевич | K13: 2.6.6. Нанотехнологии и наноматериалы (технические науки)

Sheet Лист2
A1: Аль-Амери Саджа Нафеа Мохсин | B1: АХН21
A2: Рухов Антон Викторович | B2: АХН21
A3: Хан Юлиан Александрович | B3: АХН31
A4: Наякшин Дмитрий Андреевич | B4: АЗС11
A5: Баламутова Анна Андреевна | B5: АЗС11з
A6: Зотов Евгений Сергеевич | B6: АСТ11
A7: Кейта Яя | B7: АСТ21
A8: Хайдар Фарис | B8: АСТ21
A9: Аль-Накди Ибтехаль Абдулмонем Али | B9: АСТ31
A10: Путинцева Анастасия Александровна | B10: АСТ31
A11: Альджабуби Дхафер Зейд Мохаммед | B11: АСТ41
A12: Яровая Татьяна Сергеевна | B12: АСТ41
... A158: Подлеснов Владимир Ильич | B158: АИА21з

Sheet БД приказы
A1: ФИО Полностью - в дательном падеже | B1: Д | C1: М | D1: Г | E1: № | F1: Д | G1: М | H1: Г | I1: c (приказ №, дата) | J1: Д | K1: М | L1: Г | M1: № | N1: Д | O1: М | P1: Г | Q1: по (приказ №, дата) | R1: ФИО - Фамилия+инициалы
A2: ШЕЛЬ ЕВГЕНИИ ЮРЬЕВНЕ | B2: 01 | C2: сентября | D2: 16 | E2: 962-08 | F2: 19 | G2: августа | H2: 16 | I2: =CONCATENATE("« ",B2," » ",C2, " 20",D2," г. (приказ о зачислении № ",E2," от « ",F2," » ",G2," 20",H2," г.)") -> « 01 » сентября 2016 г. (приказ о зачислении № 962-08 от « 19 » августа 2016 г.) | J2: Дата | K2: Месяц | L2: Год | M2: ??? | N2: Дата | O2: Месяц | P2: Год | Q2: =CONCATENATE("« ",J2," » ",K2, " 20",L2," г. (приказ об отчислении № ",M2," от « ",N2," » ",O2," 20",P2," г.)") -> « Дата » Месяц 20Год г. (приказ об отчислении № ??? от « Дата » Месяц 20Год г.) | R2: Шель Евгения Юрьевна
A3: ДАНИШ АБДУЛ БАРЕЙ | B3: 31 | C3: октября | D3: 16 | E3: 1402-08 | F3: 31 | G3: октября | H3: 16 | I3: =CONCATENATE("« ",B3," » ",C3, " 20",D3," г. (приказ о зачислении № ",E3," от « ",F3," » ",G3," 20",H3," г.)") -> « 31 » октября 2016 г. (приказ о зачислении № 1402-08 от « 31 » октября 2016 г.) | J3: Дата | K3: Месяц | L3: Год | M3: ??? | N3: Дата | O3: Месяц | P3: Год | Q3: =CONCATENATE("« ",J3," » ",K3, " 20",L3," г. (приказ об отчислении № ",M3," от « ",N3," » ",O3," 20",P3," г.)") -> « Дата » Месяц 20Год г. (приказ об отчислении № ??? от « Дата » Месяц 20Год г.) | R3: Даниш Абдул Барей
A4: МЕРКУШЕВОЙ НАТАЛИИ ПАВЛОВНЕ | B4: 01 | C4: сентября | D4: 16 | E4: 962-08 | F4: 19 | G4: августа | H4: 16 | I4: =CONCATENATE("« ",B4," » ",C4, " 20",D4," г. (приказ о зачислении № ",E4," от « ",F4," » ",G4," 20",H4," г.)") -> « 01 » сентября 2016 г. (приказ о зачислении № 962-08 от « 19 » августа 2016 г.) | J4: Дата | K4: Месяц | L4: Год | M4: ??? | N4: Дата | O4: Месяц | P4: Год | Q4: =CONCATENATE("« ",J4," » ",K4, " 20",L4," г. (приказ об отчислении № ",M4," от « ",N4," » ",O4," 20",P4," г.)") -> « Дата » Месяц 20Год г. (приказ об отчислении № ??? от « Дата » Месяц 20Год г.) | R4: Меркушева Наталия Павловна
A5: СТРУЛЕВОЙ ИРИНЕ АЛЕКСАНДРОВНЕ | B5: 01 | C5: сентября | D5: 16 | E5: 962-08 | F5: 19 | G5: августа | H5: 16 | I5: =CONCATENATE("« ",B5," » ",C5, " 20",D5," г. (приказ о зачислении № ",E5," от « ",F5," » ",G5," 20",H5," г.)") -> « 01 » сентября 2016 г. (приказ о зачислении № 962-08 от « 19 » августа 2016 г.) | J5: Дата | K5: Месяц | L5: Год | M5: ??? | N5: Дата | O5: Месяц | P5: Год | Q5: =CONCATENATE("« ",J5," » ",K5, " 20",L5," г. (приказ об отчислении № ",M5," от « ",N5," » ",O5," 20",P5," г.)") -> « Дата » Месяц 20Год г. (приказ об отчислении № ??? от « Дата » Месяц 20Год г.) | R5: Струлева Ирина Александровна
A6: МАЗАЛОВУ АЛЕКСАНДРУ НИКОЛАЕВИЧУ | B6: 01 | C6: сентября | D6: 16 | E6: 962-08 | F6: 19 | G6: августа | H6: 16 | I6: =CONCATENATE("« ",B6," » ",C6, " 20",D6," г. (приказ о зачислении № ",E6," от « ",F6," » ",G6," 20",H6," г.)") -> « 01 » сентября 2016 г. (приказ о зачислении № 962-08 от « 19 » августа 2016 г.) | J6: Дата | K6: Месяц | L6: Год | M6: ??? | N6: Дата | O6: Месяц | P6: Год | Q6: =CONCATENATE("« ",J6," » ",K6, " 20",L6," г. (приказ об отчислении № ",M6," от « ",N6," » ",O6," 20",P6," г.)") -> « Дата » Месяц 20Год г. (приказ об отчислении № ??? от « Дата » Месяц 20Год г.) | R6: Мазалов Александр Николаевич
A7: МИНАЕВУ ЕВГЕНИЮ АНДРЕЕВИЧУ | B7: 01 | C7: сентября | D7: 16 | E7: 962-08 | F7: 19 | G7: августа | H7: 16 | I7: =CONCATENATE("« ",B7," » ",C7, " 20",D7," г. (приказ о зачислении № ",E7," от « ",F7," » ",G7," 20",H7," г.)") -> « 01 » сентября 2016 г. (приказ о зачислении № 962-08 от « 19 » августа 2016 г.) | J7: Дата | K7: Месяц | L7: Год | M7: ??? | N7: Дата | O7: Месяц | P7: Год | Q7: =CONCATENATE("« ",J7," » ",K7, " 20",L7," г. (приказ об отчислении № ",M7," от « ",N7," » ",O7," 20",P7," г.)") -> « Дата » Месяц 20Год г. (приказ об отчислении № ??? от « Дата » Месяц 20Год г.) | R7: Минаев Евгений Андреевич
A8: ТРЕФИЛОВУ ПАВЛУ АЛЕКСАНДРОВИЧУ | B8: 01 | C8: сентября | D8: 16 | E8: 962-08 | F8: 19 | G8: августа | H8: 16 | I8: =CONCATENATE("« ",B8," » ",C8, " 20",D8," г. (приказ о зачислении № ",E8," от « ",F8," » ",G8," 20",H8," г.)") -> « 01 » сентября 2016 г. (приказ о зачислении № 962-08 от « 19 » августа 2016 г.) | J8: Дата | K8: Месяц | L8: Год | M8: ??? | N8: Дата | O8: Месяц | P8: Год | Q8: =CONCATENATE("« ",J8," » ",K8, " 20",L8," г. (приказ об отчислении № ",M8," от « ",N8," » ",O8," 20",P8," г.)") -> « Дата » Месяц 20Год г. (приказ об отчислении № ??? от « Дата » Месяц 20Год г.) | R8: Трефилов Павел Александрович
A9: СЫЧЕВУ ВЛАДИСЛАВУ АНДРЕЕВИЧУ | B9: 01 | C9: сентября | D9: 16 | E9: 962-08 | F9: 19 | G9: августа | H9: 16 | I9: =CONCATENATE("« ",B9," » ",C9, " 20",D9," г. (приказ о зачислении № ",E9," от « ",F9," » ",G9," 20",H9," г.)") -> « 01 » сентября 2016 г. (приказ о зачислении № 962-08 от « 19 » августа 2016 г.) | J9: Дата | K9: Месяц | L9: Год | M9: ??? | N9: Дата | O9: Месяц | P9: Год | Q9: =CONCATENATE("« ",J9," » ",K9, " 20",L9," г. (приказ об отчислении № ",M9," от « ",N9," » ",O9," 20",P9," г.)") -> « Дата » Месяц 20Год г. (приказ об отчислении № ??? от « Дата » Месяц 20Год г.) | R9: Сычев Владислав Андреевич
A10: АЛИЕВУ НАРИМАН ЭЛЬШАН ОГЛЫ | B10: 01 | C10: сентября | D10: 16 | E10: 962-08 | F10: 19 | G10: августа | H10: 16 | I10: =CONCATENATE("« ",B10," » ",C10, " 20",D10," г. (приказ о зачислении № ",E10," от « ",F10," » ",G10," 20",H10," г.)") -> « 01 » сентября 2016 г. (приказ о зачислении № 962-08 от « 19 » августа 2016 г.) | J10: Дата | K10: Месяц | L10: Год | M10: ??? | N10: Дата | O10: Месяц | P10: Год | Q10: =CONCATENATE("« ",J10," » ",K10, " 20",L10," г. (приказ об отчислении № ",M10," от « ",N10," » ",O10," 20",P10," г.)") -> « Дата » Месяц 20Год г. (приказ об отчислении № ??? от « Дата » Месяц 20Год г.) | R10: Алиев Нариман Эльшан оглы
A11: ТРОФИМОВУ ДЕНИСУ ВАЛЕРЬЕВИЧУ | B11: 01 | C11: сентября | D11: 15 | E11: 1016-08 | F11: 18 | G11: августа | H11: 15 | I11: =CONCATENATE("« ",B11," » ",C11, " 20",D11," г. (приказ о зачислении № ",E11," от « ",F11," » ",G11," 20",H11," г.)") -> « 01 » сентября 2015 г. (приказ о зачислении № 1016-08 от « 18 » августа 2015 г.) | J11: Дата | K11: Месяц | L11: Год | M11: ??? | N11: Дата | O11: Месяц | P11: Год | Q11: =CONCATENATE("« ",J11," » ",K11, " 20",L11," г. (приказ об отчислении № ",M11," от « ",N11," » ",O11," 20",P11," г.)") -> « Дата » Месяц 20Год г. (приказ об отчислении № ??? от « Дата » Месяц 20Год г.) | R11: Трофимов Денис Валерьевич
A12: ГОРБУНОВОЙ АНАСТАСИИ ЮРЬЕВНЕ | B12: 01 | C12: сентября | D12: 16 | E12: 962-08 | F12: 19 | G12: августа | H12: 16 | I12: =CONCATENATE("« ",B12," » ",C12, " 20",D12," г. (приказ о зачислении № ",E12," от « ",F12," » ",G12," 20",H12," г.)") -> « 01 » сентября 2016 г. (приказ о зачислении № 962-08 от « 19 » августа 2016 г.) | J12: Дата | K12: Месяц | L12: Год | M12: ??? | N12: Дата | O12: Месяц | P12: Год | Q12: =CONCATENATE("« ",J12," » ",K12, " 20",L12," г. (приказ об отчислении № ",M12," от « ",N12," » ",O12," 20",P12," г.)") -> « Дата » Месяц 20Год г. (приказ об отчислении № ??? от « Дата » Месяц 20Год г.) | R12: Горбунова Анастасия Юрьевна
A13: ЯГУБОВУ ВИКТОРУ САХИБОВИЧУ | B13: 01 | C13: сентября | D13: 16 | E13: 962-08 | F13: 19 | G13: августа | H13: 16 | I13: =CONCATENATE("« ",B13," » ",C13, " 20",D13," г. (приказ о зачислении № ",E13," от « ",F13," » ",G13," 20",H13," г.)") -> « 01 » сентября 2016 г. (приказ о зачислении № 962-08 от « 19 » августа 2016 г.) | J13: Дата | K13: Месяц | L13: Год | M13: ??? | N13: Дата | O13: Месяц | P13: Год | Q13: =CONCATENATE("« ",J13," » ",K13, " 20",L13," г. (приказ об отчислении № ",M13," от « ",N13," » ",O13," 20",P13," г.)") -> « Дата » Месяц 20Год г. (приказ об отчислении № ??? от « Дата » Месяц 20Год г.) | R13: Ягубов Виктор Сахибович
... A22: СМОЛЬСКОМУ ГРИГОРИЮ ВЛАДИМИРОВИЧУ | B22: 01 | C22: сентября | D22: 16 | E22: 963-08 | F22: 19 | G22: августа | H22: 16 | I22: =CONCATENATE("« ",B22," » ",C22, " 20",D22," г. (приказ о зачислении № ",E22," от « ",F22," » ",G22," 20",H22," г.)") -> « 01 » сентября 2016 г. (приказ о зачислении № 963-08 от « 19 » августа 2016 г.) | J22: Дата | K22: Месяц | L22: Год | M22: ??? | N22: Дата | O22: Месяц | P22: Год | Q22: =CONCATENATE("« ",J22," » ",K22, " 20",L22," г. (приказ об отчислении № ",M22," от « ",N22," » ",O22," 20",P22," г.)") -> « Дата » Месяц 20Год г. (приказ об отчислении № ??? от « Дата » Месяц 20Год г.) | R22: Смольский Григорий Владимирович
A23: ДОБРОСОЦКОМУ НИКОЛАЮ ИВАНОВИЧУ | B23: 01 | C23: сентября | D23: 16 | E23: 964-08 | F23: 19 | G23: августа | H23: 16 | I23: =CONCATENATE("« ",B23," » ",C23, " 20",D23," г. (приказ о зачислении № ",E23," от « ",F23," » ",G23," 20",H23," г.)") -> « 01 » сентября 2016 г. (приказ о зачислении № 964-08 от « 19 » августа 2016 г.) | J23: 07 | K23: июля | L23: 20 | M23: 122/7-08 | N23: 07 | O23: июля | P23: 20 | Q23: =CONCATENATE("« ",J23," » ",K23, " 20",L23," г. (приказ об отчислении № ",M23," от « ",N23," » ",O23," 20",P23," г.)") -> « 07 » июля 2020 г. (приказ об отчислении № 122/7-08 от « 07 » июля 2020 г.) | R23: Добросоцкий Николай Иванович
A24: ФАРАХШИНОЙ ИРАИДЕ ВАЛЕРЬЕВНЕ | B24: 01 | C24: сентября | D24: 15 | E24: 1023-08 | F24: 21 | G24: августа | H24: 15 | I24: =CONCATENATE("« ",B24," » ",C24, " 20",D24," г. (приказ о зачислении № ",E24," от « ",F24," » ",G24," 20",H24," г.)") -> « 01 » сентября 2015 г. (приказ о зачислении № 1023-08 от « 21 » августа 2015 г.) | J24: 07 | K24: июля | L24: 20 | M24: 122/7-08 | N24: 07 | O24: июля | P24: 20 | Q24: =CONCATENATE("« ",J24," » ",K24, " 20",L24," г. (приказ об отчислении № ",M24," от « ",N24," » ",O24," 20",P24," г.)") -> « 07 » июля 2020 г. (приказ об отчислении № 122/7-08 от « 07 » июля 2020 г.) | R24: Фарахшина Ираида Валерьевна
A25: АЛФЕДЕЙЛАТ ФЕРАС М М | B25: 27 | C25: октября | D25: 17 | E25: 1286-08 | F25: 27 | G25: октября | H25: 17 | I25: =CONCATENATE("« ",B25," » ",C25, " 20",D25," г. (приказ о зачислении № ",E25," от « ",F25," » ",G25," 20",H25," г.)") -> « 27 » октября 2017 г. (приказ о зачислении № 1286-08 от « 27 » октября 2017 г.) | J25: Дата | K25: Месяц | L25: Год | M25: ??? | N25: Дата | O25: Месяц | P25: Год | Q25: =CONCATENATE("« ",J25," » ",K25, " 20",L25," г. (приказ об отчислении № ",M25," от « ",N25," » ",O25," 20",P25," г.)") -> « Дата » Месяц 20Год г. (приказ об отчислении № ??? от « Дата » Месяц 20Год г.) | R25: Алфедейлат Ферас М М
A26: КАРГАНОВОЙ АЛИНЕ ЮРЬЕВНЕ | B26: 01 | C26: сентября | D26: 17 | E26: 895-08 | F26: 31 | G26: августа | H26: 17 | I26: =CONCATENATE("« ",B26," » ",C26, " 20",D26," г. (приказ о зачислении № ",E26," от « ",F26," » ",G26," 20",H26," г.)") -> « 01 » сентября 2017 г. (приказ о зачислении № 895-08 от « 31 » августа 2017 г.) | J26: Дата | K26: Месяц | L26: Год | M26: ??? | N26: Дата | O26: Месяц | P26: Год | Q26: =CONCATENATE("« ",J26," » ",K26, " 20",L26," г. (приказ об отчислении № ",M26," от « ",N26," » ",O26," 20",P26," г.)") -> « Дата » Месяц 20Год г. (приказ об отчислении № ??? от « Дата » Месяц 20Год г.) | R26: Карганова Алина Юрьевна
A27: ЛАКОМКИНУ НИКИТЕ АЛЕКСЕЕВИЧУ | B27: 01 | C27: сентября | D27: 17 | E27: 895-08 | F27: 31 | G27: августа | H27: 17 | I27: =CONCATENATE("« ",B27," » ",C27, " 20",D27," г. (приказ о зачислении № ",E27," от « ",F27," » ",G27," 20",H27," г.)") -> « 01 » сентября 2017 г. (приказ о зачислении № 895-08 от « 31 » августа 2017 г.) | J27: Дата | K27: Месяц | L27: Год | M27: ??? | N27: Дата | O27: Месяц | P27: Год | Q27: =CONCATENATE("« ",J27," » ",K27, " 20",L27," г. (приказ об отчислении № ",M27," от « ",N27," » ",O27," 20",P27," г.)") -> « Дата » Месяц 20Год г. (приказ об отчислении № ??? от « Дата » Месяц 20Год г.) | R27: Лакомкин Никита Алексеевич
A28: СОСЮРЕ ДАНИИЛУ ДМИТРИЕВИЧУ | B28: 01 | C28: сентября | D28: 17 | E28: 895-08 | F28: 31 | G28: августа | H28: 17 | I28: =CONCATENATE("« ",B28," » ",C28, " 20",D28," г. (приказ о зачислении № ",E28," от « ",F28," » ",G28," 20",H28," г.)") -> « 01 » сентября 2017 г. (приказ о зачислении № 895-08 от « 31 » августа 2017 г.) | J28: Дата | K28: Месяц | L28: Год | M28: ??? | N28: Дата | O28: Месяц | P28: Год | Q28: =CONCATENATE("« ",J28," » ",K28, " 20",L28," г. (приказ об отчислении № ",M28," от « ",N28," » ",O28," 20",P28," г.)") -> « Дата » Месяц 20Год г. (приказ об отчислении № ??? от « Дата » Месяц 20Год г.) | R28: Сосюра Даниил Дмитриевич
A33: КОЗЛОВОЙ ЮЛИИ АЛЕКСЕЕВНЕ | B33: Дата | C33: Месяц | D33: Год | E33: ??? | F33: Дата | G33: Месяц | H33: Год | I33: =CONCATENATE("« ",B33," » ",C33, " 20",D33," г. (приказ о зачислении № ",E33," от « ",F33," » ",G33," 20",H33," г.)") -> « Дата » Месяц 20Год г. (приказ о зачислении № ??? от « Дата » Месяц 20Год г.) | J33: Дата | K33: Месяц | L33: Год | M33: ??? | N33: Дата | O33: Месяц | P33: Год | Q33: =CONCATENATE("« ",J33," » ",K33, " 20",L33," г. (приказ об отчислении № ",M33," от « ",N33," » ",O33," 20",P33," г.)") -> « Дата » Месяц 20Год г. (приказ об отчислении № ??? от « Дата » Месяц 20Год г.) | R33: Козлова Юлия Алексеевна
A34: СУХОРУКОВОЙ ТАТЬЯНЕ АЛЕКСАНДРОВНЕ | B34: Дата | C34: Месяц | D34: Год | E34: ??? | F34: Дата | G34: Месяц | H34: Год | I34: =CONCATENATE("« ",B34," » ",C34, " 20",D34," г. (приказ о зачислении № ",E34," от « ",F34," » ",G34," 20",H34," г.)") -> « Дата » Месяц 20Год г. (приказ о зачислении № ??? от « Дата » Месяц 20Год г.) | J34: Дата | K34: Месяц | L34: Год | M34: ??? | N34: Дата | O34: Месяц | P34: Год | Q34: =CONCATENATE("« ",J34," » ",K34, " 20",L34," г. (приказ об отчислении № ",M34," от « ",N34," » ",O34," 20",P34," г.)") -> « Дата » Месяц 20Год г. (приказ об отчислении № ??? от « Дата » Месяц 20Год г.) | R34: Сухорукова Татьяна Александровна
A35: СВИТАВСКОМУ ЕВГЕНИЮ ВАЛЕРЬЕВИЧУ | B35: Дата | C35: Месяц | D35: Год | E35: ??? | F35: Дата | G35: Месяц | H35: Год | I35: =CONCATENATE("« ",B35," » ",C35, " 20",D35," г. (приказ о зачислении № ",E35," от « ",F35," » ",G35," 20",H35," г.)") -> « Дата » Месяц 20Год г. (приказ о зачислении № ??? от « Дата » Месяц 20Год г.) | J35: Дата | K35: Месяц | L35: Год | M35: ??? | N35: Дата | O35: Месяц | P35: Год | Q35: =CONCATENATE("« ",J35," » ",K35, " 20",L35," г. (приказ об отчислении № ",M35," от « ",N35," » ",O35," 20",P35," г.)") -> « Дата » Месяц 20Год г. (приказ об отчислении № ??? от « Дата » Месяц 20Год г.) | R35: Свитавский Евгений Валерьевич
A36: АПРАКСИНОЙ ОЛЬГЕ НИКОЛАЕВНЕ | B36: Дата | C36: Месяц | D36: Год | E36: ??? | F36: Дата | G36: Месяц | H36: Год | I36: =CONCATENATE("« ",B36," » ",C36, " 20",D36," г. (приказ о зачислении № ",E36," от « ",F36," » ",G36," 20",H36," г.)") -> « Дата » Месяц 20Год г. (приказ о зачислении № ??? от « Дата » Месяц 20Год г.) | J36: Дата | K36: Месяц | L36: Год | M36: ??? | N36: Дата | O36: Месяц | P36: Год | Q36: =CONCATENATE("« ",J36," » ",K36, " 20",L36," г. (приказ об отчислении № ",M36," от « ",N36," » ",O36," 20",P36," г.)") -> « Дата » Месяц 20Год г. (приказ об отчислении № ??? от « Дата » Месяц 20Год г.) | R36: Апраксина Ольга Николаевна
A37: КАРТАШОВОЙ АЛЛЕ ГЕННАДЬЕВНЕ | B37: Дата | C37: Месяц | D37: Год | E37: ??? | F37: Дата | G37: Месяц | H37: Год | I37: =CONCATENATE("« ",B37," » ",C37, " 20",D37," г. (приказ о зачислении № ",E37," от « ",F37," » ",G37," 20",H37," г.)") -> « Дата » Месяц 20Год г. (приказ о зачислении № ??? от « Дата » Месяц 20Год г.) | J37: Дата | K37: Месяц | L37: Год | M37: ??? | N37: Дата | O37: Месяц | P37: Год | Q37: =CONCATENATE("« ",J37," » ",K37, " 20",L37," г. (приказ об отчислении № ",M37," от « ",N37," » ",O37," 20",P37," г.)") -> « Дата » Месяц 20Год г. (приказ об отчислении № ??? от « Дата » Месяц 20Год г.) | R37: Карташова Алла Геннадьевна
A38: СУОП КАМТО ПОЛИН | B38: Дата | C38: Месяц | D38: Год | E38: ??? | F38: Дата | G38: Месяц | H38: Год | I38: =CONCATENATE("« ",B38," » ",C38, " 20",D38," г. (приказ о зачислении № ",E38," от « ",F38," » ",G38," 20",H38," г.)") -> « Дата » Месяц 20Год г. (приказ о зачислении № ??? от « Дата » Месяц 20Год г.) | J38: Дата | K38: Месяц | L38: Год | M38: ??? | N38: Дата | O38: Месяц | P38: Год | Q38: =CONCATENATE("« ",J38," » ",K38, " 20",L38," г. (приказ об отчислении № ",M38," от « ",N38," » ",O38," 20",P38," г.)") -> « Дата » Месяц 20Год г. (приказ об отчислении № ??? от « Дата » Месяц 20Год г.) | R38: Суоп Камто Полин

Sheet БД направление
A1: ФИО Полностью - в дательном падеже | B1: ФИО | C1: Шифр | D1: Направление | E1: направление подготовки научно-педагогических кадров в аспирантуре | F1: Профиль | G1: по образовательной программе, соответствующей специальности научных работников | H1: Дисциплина профиля Б1.В.ОД.4
A2: ШЕЛЬ ЕВГЕНИИ ЮРЬЕВНЕ | B2: Шель Евгения Юрьевна | C2: 04.06.01 | D2: Химические науки | E2: =CONCATENATE(C2," ",D2) -> 04.06.01 Химические науки | F2: 04.06.01.01 | G2: =VLOOKUP(F2,'проф - дисц - спец'!$A:$E,5,0) -> 02.00.05 Электрохимия | H2: =VLOOKUP(F2,'проф - дисц - спец'!$A:$E,2,0) -> Электрохимия
A3: ДАНИШ АБДУЛ БАРЕЙ | B3: Даниш Абдул Барей | C3: 08.06.01 | D3: Техника и технология строительства | E3: =CONCATENATE(C3," ",D3) -> 08.06.01 Техника и технология строительства | F3: 08.06.01.01 | G3: =VLOOKUP(F3,'проф - дисц - спец'!$A:$E,5,0) -> 05.23.01 Строительные конструкции, здания и сооружения | H3: =VLOOKUP(F3,'проф - дисц - спец'!$A:$E,2,0) -> Строительные конструкции, здания и сооружения
A4: МЕРКУШЕВОЙ НАТАЛИИ ПАВЛОВНЕ | B4: Меркушева Наталия Павловна | C4: 08.06.01 | D4: Техника и технология строительства | E4: =CONCATENATE(C4," ",D4) -> 08.06.01 Техника и технология строительства | F4: 08.06.01.01 | G4: =VLOOKUP(F4,'проф - дисц - спец'!$A:$E,5,0) -> 05.23.01 Строительные конструкции, здания и сооружения | H4: =VLOOKUP(F4,'проф - дисц - спец'!$A:$E,2,0) -> Строительные конструкции, здания и сооружения
A5: КОЗЛОВОЙ ЮЛИИ АЛЕКСЕЕВНЕ | B5: Козлова Юлия Алексеевна | C5: 08.06.01 | D5: Техника и технология строительства | E5: =CONCATENATE(C5," ",D5) -> 08.06.01 Техника и технология строительства | F5: 08.06.01.02 | G5: =VLOOKUP(F5,'проф - дисц - спец'!$A:$E,5,0) -> 05.23.05 Строительные материалы и изделия | H5: =VLOOKUP(F5,'проф - дисц - спец'!$A:$E,2,0) -> Строительные материалы и изделия
A6: СТРУЛЕВОЙ ИРИНЕ АЛЕКСАНДРОВНЕ | B6: Струлева Ирина Александровна | C6: 08.06.01 | D6: Техника и технология строительства | E6: =CONCATENATE(C6," ",D6) -> 08.06.01 Техника и технология строительства | F6: 08.06.01.02 | G6: =VLOOKUP(F6,'проф - дисц - спец'!$A:$E,5,0) -> 05.23.05 Строительные материалы и изделия | H6: =VLOOKUP(F6,'проф - дисц - спец'!$A:$E,2,0) -> Строительные материалы и изделия
A7: МАЗАЛОВУ АЛЕКСАНДРУ НИКОЛАЕВИЧУ | B7: Мазалов Александр Николаевич | C7: 09.06.01 | D7: Информатика и вычислительная техника | E7: =CONCATENATE(C7," ",D7) -> 09.06.01 Информатика и вычислительная техника | F7: 09.06.01.05 | G7: =VLOOKUP(F7,'проф - дисц - спец'!$A:$E,5,0) -> 05.25.05 Информационные системы и процессы | H7: =VLOOKUP(F7,'проф - дисц - спец'!$A:$E,2,0) -> Информационные системы и процессы
A8: МИНАЕВУ ЕВГЕНИЮ АНДРЕЕВИЧУ | B8: Минаев Евгений Андреевич | C8: 09.06.01 | D8: Информатика и вычислительная техника | E8: =CONCATENATE(C8," ",D8) -> 09.06.01 Информатика и вычислительная техника | F8: 09.06.01.05 | G8: =VLOOKUP(F8,'проф - дисц - спец'!$A:$E,5,0) -> 05.25.05 Информационные системы и процессы | H8: =VLOOKUP(F8,'проф - дисц - спец'!$A:$E,2,0) -> Информационные системы и процессы
A9: ТРЕФИЛОВУ ПАВЛУ АЛЕКСАНДРОВИЧУ | B9: Трефилов Павел Александрович | C9: 09.06.01 | D9: Информатика и вычислительная техника | E9: =CONCATENATE(C9," ",D9) -> 09.06.01 Информатика и вычислительная техника | F9: 09.06.01.05 | G9: =VLOOKUP(F9,'проф - дисц - спец'!$A:$E,5,0) -> 05.25.05 Информационные системы и процессы | H9: =VLOOKUP(F9,'проф - дисц - спец'!$A:$E,2,0) -> Информационные системы и процессы
A10: СЫЧЕВУ ВЛАДИСЛАВУ АНДРЕЕВИЧУ | B10: Сычев Владислав Андреевич | C10: 12.06.01 | D10: Фотоника, приборостроение, оптические и биотехнические системы и технологии | E10: =CONCATENATE(C10," ",D10) -> 12.06.01 Фотоника, приборостроение, оптические и биотехнические системы и технологии | F10: 12.06.01.01 | G10: =VLOOKUP(F10,'проф - дисц - спец'!$A:$E,5,0) -> 05.11.13 Приборы и методы контроля природной среды, веществ, материалов и изделий | H10: =VLOOKUP(F10,'проф - дисц - спец'!$A:$E,2,0) -> Приборы и системы контроля природной среды, веществ, материалов и изделий
A11: АЛИЕВУ НАРИМАН ЭЛЬШАН ОГЛЫ | B11: Алиев Нариман Эльшан оглы | C11: 12.06.01 | D11: Фотоника, приборостроение, оптические и биотехнические системы и технологии | E11: =CONCATENATE(C11," ",D11) -> 12.06.01 Фотоника, приборостроение, оптические и биотехнические системы и технологии | F11: 12.06.01.02 | G11: =VLOOKUP(F11,'проф - дисц - спец'!$A:$E,5,0) -> 05.11.17 Приборы, системы и изделия медицинского назначения | H11: =VLOOKUP(F11,'проф - дисц - спец'!$A:$E,2,0) -> Приборы, системы, изделия медицинского назначения
A12: ТРОФИМОВУ ДЕНИСУ ВАЛЕРЬЕВИЧУ | B12: Трофимов Денис Валерьевич | C12: 12.06.01 | D12: Фотоника, приборостроение, оптические и биотехнические системы и технологии | E12: =CONCATENATE(C12," ",D12) -> 12.06.01 Фотоника, приборостроение, оптические и биотехнические системы и технологии | F12: 12.06.01.03 | G12: =VLOOKUP(F12,'проф - дисц - спец'!$A:$E,5,0) -> 05.11.16 Информационноизмерительные и управляющие системы (по отраслям) | H12: =VLOOKUP(F12,'проф - дисц - спец'!$A:$E,2,0) -> Информационно-измерительные и управляющие системы
A13: ГОРБУНОВОЙ АНАСТАСИИ ЮРЬЕВНЕ | B13: Горбунова Анастасия Юрьевна | C13: 12.06.01 | D13: Фотоника, приборостроение, оптические и биотехнические системы и технологии | E13: =CONCATENATE(C13," ",D13) -> 12.06.01 Фотоника, приборостроение, оптические и биотехнические системы и технологии | F13: 12.06.01.03 | G13: =VLOOKUP(F13,'проф - дисц - спец'!$A:$E,5,0) -> 05.11.16 Информационноизмерительные и управляющие системы (по отраслям) | H13: =VLOOKUP(F13,'проф - дисц - спец'!$A:$E,2,0) -> Информационно-измерительные и управляющие системы
... A34: СОСЮРЕ ДАНИИЛУ ДМИТРИЕВИЧУ | B34: Сосюра Даниил Дмитриевич | C34: 41.06.01 | D34: Политические науки и регионоведение | E34: =CONCATENATE(C34," ",D34) -> 41.06.01 Политические науки и регионоведение | F34: 41.06.01.01 | G34: =VLOOKUP(F34,'проф - дисц - спец'!$A:$E,5,0) -> 23.00.02 Политические институты, процессы и технологии | H34: =VLOOKUP(F34,'проф - дисц - спец'!$A:$E,2,0) -> Политические институты, процессы и технологии

Sheet БД Таблица
A1: ФИО Полностью - в дательном падеже | B1: Название предмета 1 | C1: Оценка | D1: Дата | E1: год | F1: Оценка и дата сдачи экзамена | G1: Председатель комиссии: | H1: Член комиссии 1 | I1: Член комиссии 2 | J1: Члены комиссии: | K1: Название предмета 2 | L1: Оценка | M1: Дата | N1: год | O1: Оценка и дата сдачи экзамена | P1: Председатель комиссии: | Q1: Член комиссии 1 | R1: Член комиссии 2 | S1: Член комиссии 3 | T1: Члены комиссии: | U1: Название предмета 3 | V1: Оценка | W1: Дата | X1: год | Y1: Оценка и дата сдачи экзамена | Z1: Председатель комиссии: | AA1: Член комиссии 1 | AB1: Член комиссии 2 | AC1: Члены комиссии:
A2: ШЕЛЬ ЕВГЕНИИ ЮРЬЕВНЕ | B2: История и философия науки | C2: Отлично | D2: 24 января | E2: 2017 | F2: =CONCATENATE(C2,CHAR(10),D2,CHAR(10),E2," года") -> Отлично 24 января 2017 года | G2: Юдин А.И., доктор философских наук, профессор, профессор кафедры «История и философия». | H2: Слезин А.А., доктор исторических наук, профессор, зав. кафедрой «История и философия», заместитель председателя комиссии; | I2: Самохин К.В., кандидат исторических наук, доцент, доцент кафедры «История и философия» | J2: =CONCATENATE(H2,CHAR(10),I2) -> Слезин А.А., доктор исторических наук, профессор, зав. кафедрой «История и философия», заместитель председателя комиссии; Самохин К.В., кандидат исторических наук, доцент, доцент кафедры «История и философия» | K2: Иностранный язык | L2: Отлично | M2: 22 июня | N2: 2017 | O2: =CONCATENATE(L2,CHAR(10),M2,CHAR(10),N2," года") -> Отлично 22 июня 2017 года | P2: Макеева М.Н., доктор филологических наук, профессор, зав. кафедрой «Иностранный язык» | Q2: Гунина Н.А., кандидат филологических наук, доцент, зав. кафедрой «Международная профессиональная и научная коммуникация», заместитель председателя комиссии; | R2: Королева Л.Ю., кандидат филологических наук, доцент, доцент кафедры «Международная профессиональная и научная коммуникация»; | S2: Зарапина И.В., кандидат химических наук, доцент, доцент кафедры «Химия и химические технологии» | T2: =CONCATENATE(Q2,CHAR(10),R2,CHAR(10),S2) -> Гунина Н.А., кандидат филологических наук, доцент, зав. кафедрой «Международная профессиональная и научная коммуникация», заместитель председателя комиссии; Королева Л.Ю., кандидат филологических наук, доцент, доцент кафедры «Международная профессиональная и научная коммуникация»; Зарапина И.В., кандидат химических наук, доцент, доцент кафедры «Химия и химические технологии» | U2: =VLOOKUP(A2,'БД направление'!$A:$H,8,0) -> Электрохимия | V2: Отлично | W2: 27 июня | X2: 2019 | Y2: =CONCATENATE(V2,CHAR(10),W2,CHAR(10),X2," года") -> Отлично 27 июня 2019 года | Z2: Рухов А.В., доктор технических наук, доцент, заведующий кафедрой «Химия и химические технологии» | AA2: Дьячкова Т.П., доктор химических наук, доцент, доцент кафедры "Химия и химические технологии", заместитель председателя комиссии; | AB2: Зарапина И.В., кандидат химических наук, доцент, доцент кафедры «Химия и химические технологии» | AC2: =CONCATENATE(AA2,CHAR(10),AB2) -> Дьячкова Т.П., доктор химических наук, доцент, доцент кафедры "Химия и химические технологии", заместитель председателя комиссии; Зарапина И.В., кандидат химических наук, доцент, доцент кафедры «Химия и химические технологии»
A3: ДАНИШ АБДУЛ БАРЕЙ | B3: История и философия науки | C3: Отлично | D3: 21 января | E3: 2017 | F3: =CONCATENATE(C3,CHAR(10),D3,CHAR(10),E3," года") -> Отлично 21 января 2017 года | G3: Юдин А.И., доктор философских наук, профессор, профессор кафедры «История и философия». | H3: Слезин А.А., доктор исторических наук, профессор, зав. кафедрой «История и философия», заместитель председателя комиссии; | I3: Терехова Г.Л., кандидат философских наук, доцент, доцент кафедры «История и философия» | J3: =CONCATENATE(H3,CHAR(10),I3) -> Слезин А.А., доктор исторических наук, профессор, зав. кафедрой «История и философия», заместитель председателя комиссии; Терехова Г.Л., кандидат философских наук, доцент, доцент кафедры «История и философия» | K3: Иностранный язык | L3: Отлично | M3: 20 июня | N3: 2017 | O3: =CONCATENATE(L3,CHAR(10),M3,CHAR(10),N3," года") -> Отлично 20 июня 2017 года | P3: Макеева М.Н., доктор филологических наук, профессор, зав. кафедрой «Иностранный язык» | Q3: Бородулина Н.Ю., доктор филологических наук, доцент, профессор кафедры «Иностранных языков», заместитель председателя комиссии | R3: Гуляева Е.А., кандидат педагогических наук, доцент, доцент кафедры «Иностранных языков» | S3: Червяков В.М., доктор технических наук, доцент, профессор кафедры «Техническая механика и детали машин» | T3: =CONCATENATE(Q3,CHAR(10),R3,CHAR(10),S3) -> Бородулина Н.Ю., доктор филологических наук, доцент, профессор кафедры «Иностранных языков», заместитель председателя комиссии Гуляева Е.А., кандидат педагогических наук, доцент, доцент кафедры «Иностранных языков» Червяков В.М., доктор технических наук, доцент, профессор кафедры «Техническая механика и детали машин» | U3: =VLOOKUP(A3,'БД направление'!$A:$H,8,0) -> Строительные конструкции, здания и сооружения | V3: Отлично | W3: 27 июня | X3: 2019 | Y3: =CONCATENATE(V3,CHAR(10),W3,CHAR(10),X3," года") -> Отлично 27 июня 2019 года | Z3: Ярцев В.П., доктор технических наук, профессор, профессор кафедры «Конструкции зданий и сооружений» | AA3: Леденев В.В., доктор технических наук, профессор, профессор кафедры «Конструкции зданий и сооружений», заместитель председателя комиссии | AB3: Леденев В.И., доктор технических наук, профессор, профессор кафедры «Городское строительство и автомобильные дороги» | AC3: =CONCATENATE(AA3,CHAR(10),AB3) -> Леденев В.В., доктор технических наук, профессор, профессор кафедры «Конструкции зданий и сооружений», заместитель председателя комиссии Леденев В.И., доктор технических наук, профессор, профессор кафедры «Городское строительство и автомобильные дороги»
A4: МЕРКУШЕВОЙ НАТАЛИИ ПАВЛОВНЕ | B4: История и философия науки | C4: Отлично | D4: 24 января | E4: 2017 | F4: =CONCATENATE(C4,CHAR(10),D4,CHAR(10),E4," года") -> Отлично 24 января 2017 года | G4: Юдин А.И., доктор философских наук, профессор, профессор кафедры «История и философия». | H4: Слезин А.А., доктор исторических наук, профессор, зав. кафедрой «История и философия», заместитель председателя комиссии; | I4: Терехова Г.Л., кандидат философских наук, доцент, доцент кафедры «История и философия» | J4: =CONCATENATE(H4,CHAR(10),I4) -> Слезин А.А., доктор исторических наук, профессор, зав. кафедрой «История и философия», заместитель председателя комиссии; Терехова Г.Л., кандидат философских наук, доцент, доцент кафедры «История и философия» | K4: Иностранный язык | L4: Отлично | M4: 20 июня | N4: 2017 | O4: =CONCATENATE(L4,CHAR(10),M4,CHAR(10),N4," года") -> Отлично 20 июня 2017 года | P4: Макеева М.Н., доктор филологических наук, профессор, зав. кафедрой «Иностранный язык» | Q4: Гунина Н.А., кандидат филологических наук, доцент, зав. кафедрой «Международная профессиональная и научная коммуникация», заместитель председателя комиссии; | R4: Королева Л.Ю., кандидат филологических наук, доцент, доцент кафедры «Международная профессиональная и научная коммуникация»; | S4: Монастырев П.В., доктор технических наук, доцент, директор института архитектуры, строительства и транспорта | T4: =CONCATENATE(Q4,CHAR(10),R4,CHAR(10),S4) -> Гунина Н.А., кандидат филологических наук, доцент, зав. кафедрой «Международная профессиональная и научная коммуникация», заместитель председателя комиссии; Королева Л.Ю., кандидат филологических наук, доцент, доцент кафедры «Международная профессиональная и научная коммуникация»; Монастырев П.В., доктор технических наук, доцент, директор института архитектуры, строительства и транспорта | U4: =VLOOKUP(A4,'БД направление'!$A:$H,8,0) -> Строительные конструкции, здания и сооружения | V4: Отлично | W4: 27 июня | X4: 2019 | Y4: =CONCATENATE(V4,CHAR(10),W4,CHAR(10),X4," года") -> Отлично 27 июня 2019 года | Z4: Ярцев В.П., доктор технических наук, профессор, профессор кафедры «Конструкции зданий и сооружений» | AA4: Леденев В.В., доктор технических наук, профессор, профессор кафедры «Конструкции зданий и сооружений», заместитель председателя комиссии | AB4: Леденев В.И., доктор технических наук, профессор, профессор кафедры «Городское строительство и автомобильные дороги» | AC4: =CONCATENATE(AA4,CHAR(10),AB4) -> Леденев В.В., доктор технических наук, профессор, профессор кафедры «Конструкции зданий и сооружений», заместитель председателя комиссии Леденев В.И., доктор технических наук, профессор, профессор кафедры «Городское строительство и автомобильные дороги»
A5: СТРУЛЕВОЙ ИРИНЕ АЛЕКСАНДРОВНЕ | B5: История и философия науки | C5: Отлично | D5: 24 января | E5: 2017 | F5: =CONCATENATE(C5,CHAR(10),D5,CHAR(10),E5," года") -> Отлично 24 января 2017 года | G5: Юдин А.И., доктор философских наук, профессор, профессор кафедры «История и философия». | H5: Слезин А.А., доктор исторических наук, профессор, зав. кафедрой «История и философия», заместитель председателя комиссии; | I5: Терехова Г.Л., кандидат философских наук, доцент, доцент кафедры «История и философия» | J5: =CONCATENATE(H5,CHAR(10),I5) -> Слезин А.А., доктор исторических наук, профессор, зав. кафедрой «История и философия», заместитель председателя комиссии; Терехова Г.Л., кандидат философских наук, доцент, доцент кафедры «История и философия» | K5: Иностранный язык | L5: Отлично | M5: 20 июня | N5: 2017 | O5: =CONCATENATE(L5,CHAR(10),M5,CHAR(10),N5," года") -> Отлично 20 июня 2017 года | P5: Макеева М.Н., доктор филологических наук, профессор, зав. кафедрой «Иностранный язык» | Q5: Гунина Н.А., кандидат филологических наук, доцент, зав. кафедрой «Международная профессиональная и научная коммуникация», заместитель председателя комиссии; | R5: Королева Л.Ю., кандидат филологических наук, доцент, доцент кафедры «Международная профессиональная и научная коммуникация»; | S5: Монастырев П.В., доктор технических наук, доцент, директор института архитектуры, строительства и транспорта | T5: =CONCATENATE(Q5,CHAR(10),R5,CHAR(10),S5) -> Гунина Н.А., кандидат филологических наук, доцент, зав. кафедрой «Международная профессиональная и научная коммуникация», заместитель председателя комиссии; Королева Л.Ю., кандидат филологических наук, доцент, доцент кафедры «Международная профессиональная и научная коммуникация»; Монастырев П.В., доктор технических наук, доцент, директор института архитектуры, строительства и транспорта | U5: =VLOOKUP(A5,'БД направление'!$A:$H,8,0) -> Строительные материалы и изделия | V5: Отлично | W5: 28 июня | X5: 2019 | Y5: =CONCATENATE(V5,CHAR(10),W5,CHAR(10),X5," года") -> Отлично 28 июня 2019 года | Z5: Ярцев В.П., доктор технических наук, профессор, профессор кафедры «Конструкции зданий и сооружений» | AA5: Леденев В.В., доктор технических наук, профессор, профессор кафедры «Конструкции зданий и сооружений», заместитель председателя комиссии | AB5: Монастырев П.В., доктор технических наук, доцент, директор института архитектуры, строительства и транспорта | AC5: =CONCATENATE(AA5,CHAR(10),AB5) -> Леденев В.В., доктор технических наук, профессор, профессор кафедры «Конструкции зданий и сооружений», заместитель председателя комиссии Монастырев П.В., доктор технических наук, доцент, директор института архитектуры, строительства и транспорта
A6: МАЗАЛОВУ АЛЕКСАНДРУ НИКОЛАЕВИЧУ | B6: История и философия науки | C6: Отлично | D6: 25 января | E6: 2017 | F6: =CONCATENATE(C6,CHAR(10),D6,CHAR(10),E6," года") -> Отлично 25 января 2017 года | G6: Юдин А.И., доктор философских наук, профессор, профессор кафедры «История и философия». | H6: Слезин А.А., доктор исторических наук, профессор, зав. кафедрой «История и философия», заместитель председателя комиссии; | I6: Терехова Г.Л., кандидат философских наук, доцент, доцент кафедры «История и философия» | J6: =CONCATENATE(H6,CHAR(10),I6) -> Слезин А.А., доктор исторических наук, профессор, зав. кафедрой «История и философия», заместитель председателя комиссии; Терехова Г.Л., кандидат философских наук, доцент, доцент кафедры «История и философия» | K6: Иностранный язык | L6: Отлично | M6: 20 июня | N6: 2017 | O6: =CONCATENATE(L6,CHAR(10),M6,CHAR(10),N6," года") -> Отлично 20 июня 2017 года | P6: Макеева М.Н., доктор филологических наук, профессор, зав. кафедрой «Иностранный язык» | Q6: Гунина Н.А., кандидат филологических наук, доцент, зав. кафедрой «Международная профессиональная и научная коммуникация», заместитель председателя комиссии; | R6: Королева Л.Ю., кандидат филологических наук, доцент, доцент кафедры «Международная профессиональная и научная коммуникация»; | S6: Иванова О.Г., кандидат технических наук, доцент, профессор кафедры «Информационные системы и защита информации» | T6: =CONCATENATE(Q6,CHAR(10),R6,CHAR(10),S6) -> Гунина Н.А., кандидат филологических наук, доцент, зав. кафедрой «Международная профессиональная и научная коммуникация», заместитель председателя комиссии; Королева Л.Ю., кандидат филологических наук, доцент, доцент кафедры «Международная профессиональная и научная коммуникация»; Иванова О.Г., кандидат технических наук, доцент, профессор кафедры «Информационные системы и защита информации» | U6: =VLOOKUP(A6,'БД направление'!$A:$H,8,0) -> Информационные системы и процессы | V6: Отлично | Y6: =CONCATENATE(V6,CHAR(10),W6,CHAR(10),X6," года") -> Отлично года | Z6: Громов Ю.Ю., доктор технических наук, профессор, директор института автоматики и информационных технологий | AA6: Тютюнник В.М., доктор технических наук, профессор, профессор кафедры «Конструирование радиоэлектронных и микропроцессорных систем», заместитель председателя комиссии | AB6: Дидрих В.Е., доктор технических наук, профессор, профессор кафедры «Информационные системы и защита информации» | AC6: =CONCATENATE(AA6,CHAR(10),AB6) -> Тютюнник В.М., доктор технических наук, профессор, профессор кафедры «Конструирование радиоэлектронных и микропроцессорных систем», заместитель председателя комиссии Дидрих В.Е., доктор технических наук, профессор, профессор кафедры «Информационные системы и защита информации»
A7: МИНАЕВУ ЕВГЕНИЮ АНДРЕЕВИЧУ | B7: История и философия науки | C7: Хорошо | D7: 25 января | E7: 2017 | F7: =CONCATENATE(C7,CHAR(10),D7,CHAR(10),E7," года") -> Хорошо 25 января 2017 года | G7: Юдин А.И., доктор философских наук, профессор, профессор кафедры «История и философия». | H7: Слезин А.А., доктор исторических наук, профессор, зав. кафедрой «История и философия», заместитель председателя комиссии; | I7: Терехова Г.Л., кандидат философских наук, доцент, доцент кафедры «История и философия» | J7: =CONCATENATE(H7,CHAR(10),I7) -> Слезин А.А., доктор исторических наук, профессор, зав. кафедрой «История и философия», заместитель председателя комиссии; Терехова Г.Л., кандидат философских наук, доцент, доцент кафедры «История и философия» | K7: Иностранный язык | L7: Отлично | M7: 20 июня | N7: 2017 | O7: =CONCATENATE(L7,CHAR(10),M7,CHAR(10),N7," года") -> Отлично 20 июня 2017 года | P7: Макеева М.Н., доктор филологических наук, профессор, зав. кафедрой «Иностранный язык» | Q7: Бородулина Н.Ю., доктор филологических наук, доцент, профессор кафедры «Иностранных языков», заместитель председателя комиссии | R7: Гуляева Е.А., кандидат педагогических наук, доцент, доцент кафедры «Иностранных языков» | S7: Червяков В.М., доктор технических наук, доцент, профессор кафедры «Техническая механика и детали машин» | T7: =CONCATENATE(Q7,CHAR(10),R7,CHAR(10),S7) -> Бородулина Н.Ю., доктор филологических наук, доцент, профессор кафедры «Иностранных языков», заместитель председателя комиссии Гуляева Е.А., кандидат педагогических наук, доцент, доцент кафедры «Иностранных языков» Червяков В.М., доктор технических наук, доцент, профессор кафедры «Техническая механика и детали машин» | U7: =VLOOKUP(A7,'БД направление'!$A:$H,8,0) -> Информационные системы и процессы | V7: Хорошо | Y7: =CONCATENATE(V7,CHAR(10),W7,CHAR(10),X7," года") -> Хорошо года | Z7: Громов Ю.Ю., доктор технических наук, профессор, директор института автоматики и информационных технологий | AA7: Тютюнник В.М., доктор технических наук, профессор, профессор кафедры «Конструирование радиоэлектронных и микропроцессорных систем», заместитель председателя комиссии | AB7: Дидрих В.Е., доктор технических наук, профессор, профессор кафедры «Информационные системы и защита информации» | AC7: =CONCATENATE(AA7,CHAR(10),AB7) -> Тютюнник В.М., доктор технических наук, профессор, профессор кафедры «Конструирование радиоэлектронных и микропроцессорных систем», заместитель председателя комиссии Дидрих В.Е., доктор технических наук, профессор, профессор кафедры «Информационные системы и защита информации»
A8: ТРЕФИЛОВУ ПАВЛУ АЛЕКСАНДРОВИЧУ | B8: История и философия науки | C8: Хорошо | D8: 25 января | E8: 2017 | F8: =CONCATENATE(C8,CHAR(10),D8,CHAR(10),E8," года") -> Хорошо 25 января 2017 года | G8: Юдин А.И., доктор философских наук, профессор, профессор кафедры «История и философия». | H8: Слезин А.А., доктор исторических наук, профессор, зав. кафедрой «История и философия», заместитель председателя комиссии; | I8: Терехова Г.Л., кандидат философских наук, доцент, доцент кафедры «История и философия» | J8: =CONCATENATE(H8,CHAR(10),I8) -> Слезин А.А., доктор исторических наук, профессор, зав. кафедрой «История и философия», заместитель председателя комиссии; Терехова Г.Л., кандидат философских наук, доцент, доцент кафедры «История и философия» | K8: Иностранный язык | L8: Отлично | M8: 21 июня | N8: 2017 | O8: =CONCATENATE(L8,CHAR(10),M8,CHAR(10),N8," года") -> Отлично 21 июня 2017 года | P8: Макеева М.Н., доктор филологических наук, профессор, зав. кафедрой «Иностранный язык» | Q8: Гунина Н.А., кандидат филологических наук, доцент, зав. кафедрой «Международная профессиональная и научная коммуникация», заместитель председателя комиссии; | R8: Королева Л.Ю., кандидат филологических наук, доцент, доцент кафедры «Международная профессиональная и научная коммуникация»; | S8: Иванова О.Г., кандидат технических наук, доцент, профессор кафедры «Информационные системы и защита информации» | T8: =CONCATENATE(Q8,CHAR(10),R8,CHAR(10),S8) -> Гунина Н.А., кандидат филологических наук, доцент, зав. кафедрой «Международная профессиональная и научная коммуникация», заместитель председателя комиссии; Королева Л.Ю., кандидат филологических наук, доцент, доцент кафедры «Международная профессиональная и научная коммуникация»; Иванова О.Г., кандидат технических наук, доцент, профессор кафедры «Информационные системы и защита информации» | U8: =VLOOKUP(A8,'БД направление'!$A:$H,8,0) -> Информационные системы и процессы | V8: Отлично | Y8: =CONCATENATE(V8,CHAR(10),W8,CHAR(10),X8," года") -> Отлично года | Z8: Громов Ю.Ю., доктор технических наук, профессор, директор института автоматики и информационных технологий | AA8: Тютюнник В.М., доктор технических наук, профессор, профессор кафедры «Конструирование радиоэлектронных и микропроцессорных систем», заместитель председателя комиссии | AB8: Дидрих В.Е., доктор технических наук, профессор, профессор кафедры «Информационные системы и защита информации» | AC8: =CONCATENATE(AA8,CHAR(10),AB8) -> Тютюнник В.М., доктор технических наук, профессор, профессор кафедры «Конструирование радиоэлектронных и микропроцессорных систем», заместитель председателя комиссии Дидрих В.Е., доктор технических наук, профессор, профессор кафедры «Информационные системы и защита информации»
A9: СЫЧЕВУ ВЛАДИСЛАВУ АНДРЕЕВИЧУ | B9: История и философия науки | C9: Хорошо | D9: 26 января | E9: 2017 | F9: =CONCATENATE(C9,CHAR(10),D9,CHAR(10),E9," года") -> Хорошо 26 января 2017 года | G9: Юдин А.И., доктор философских наук, профессор, профессор кафедры «История и философия». | H9: Слезин А.А., доктор исторических наук, профессор, зав. кафедрой «История и философия», заместитель председателя комиссии; | I9: Терехова Г.Л., кандидат философских наук, доцент, доцент кафедры «История и философия» | J9: =CONCATENATE(H9,CHAR(10),I9) -> Слезин А.А., доктор исторических наук, профессор, зав. кафедрой «История и философия», заместитель председателя комиссии; Терехова Г.Л., кандидат философских наук, доцент, доцент кафедры «История и философия» | K9: Иностранный язык | L9: Отлично | M9: 21 июня | N9: 2017 | O9: =CONCATENATE(L9,CHAR(10),M9,CHAR(10),N9," года") -> Отлично 21 июня 2017 года | P9: Макеева М.Н., доктор филологических наук, профессор, зав. кафедрой «Иностранный язык» | Q9: Григорьева В.С., кандидат филологических наук, доцент, профессор кафедры «Иностранных языков», заместитель председателя комиссии | R9: Чеботарева Г.Н., кандидат филологических наук, ст. преподаватель кафедры «Международная профессиональная и научная коммуникация» | S9: Фролов С.В., доктор технических наук, профессор, зав. кафедрой «Биомедицинская техника» | T9: =CONCATENATE(Q9,CHAR(10),R9,CHAR(10),S9) -> Григорьева В.С., кандидат филологических наук, доцент, профессор кафедры «Иностранных языков», заместитель председателя комиссии Чеботарева Г.Н., кандидат филологических наук, ст. преподаватель кафедры «Международная профессиональная и научная коммуникация» Фролов С.В., доктор технических наук, профессор, зав. кафедрой «Биомедицинская техника» | U9: =VLOOKUP(A9,'БД направление'!$A:$H,8,0) -> Приборы и системы контроля природной среды, веществ, материалов и изделий | V9: Отлично | W9: 25 июня | X9: 2019 | Y9: =CONCATENATE(V9,CHAR(10),W9,CHAR(10),X9," года") -> Отлично 25 июня 2019 года | Z9: Дивин А.Г., доктор технических наук, доцент, зав. кафедрой «Мехатроника и технологические измерения» | AA9: Пономарев С.В., доктор технических наук, профессор, профессор кафедры «Мехатроника и технологические измерения», заместитель председателя комиссии | AB9: Балабанов П.В., доктор технических наук, доцент, доцент кафедры «Мехатроника и технологические измерения» | AC9: =CONCATENATE(AA9,CHAR(10),AB9) -> Пономарев С.В., доктор технических наук, профессор, профессор кафедры «Мехатроника и технологические измерения», заместитель председателя комиссии Балабанов П.В., доктор технических наук, доцент, доцент кафедры «Мехатроника и технологические измерения»
A10: АЛИЕВУ НАРИМАН ЭЛЬШАН ОГЛЫ | B10: История и философия науки | C10: Отлично | D10: 26 января | E10: 2017 | F10: =CONCATENATE(C10,CHAR(10),D10,CHAR(10),E10," года") -> Отлично 26 января 2017 года | G10: Юдин А.И., доктор философских наук, профессор, профессор кафедры «История и философия». | H10: Слезин А.А., доктор исторических наук, профессор, зав. кафедрой «История и философия», заместитель председателя комиссии; | I10: Терехова Г.Л., кандидат философских наук, доцент, доцент кафедры «История и философия» | J10: =CONCATENATE(H10,CHAR(10),I10) -> Слезин А.А., доктор исторических наук, профессор, зав. кафедрой «История и философия», заместитель председателя комиссии; Терехова Г.Л., кандидат философских наук, доцент, доцент кафедры «История и философия» | K10: Иностранный язык | L10: Отлично | M10: 21 июня | N10: 2017 | O10: =CONCATENATE(L10,CHAR(10),M10,CHAR(10),N10," года") -> Отлично 21 июня 2017 года | P10: Макеева М.Н., доктор филологических наук, профессор, зав. кафедрой «Иностранный язык» | Q10: Гунина Н.А., кандидат филологических наук, доцент, зав. кафедрой «Международная профессиональная и научная коммуникация», заместитель председателя комиссии; | R10: Королева Л.Ю., кандидат филологических наук, доцент, доцент кафедры «Международная профессиональная и научная коммуникация»; | S10: Пономарев С.В., доктор технических наук, профессор, профессор кафедры «Мехатроника и технологические измерения» | T10: =CONCATENATE(Q10,CHAR(10),R10,CHAR(10),S10) -> Гунина Н.А., кандидат филологических наук, доцент, зав. кафедрой «Международная профессиональная и научная коммуникация», заместитель председателя комиссии; Королева Л.Ю., кандидат филологических наук, доцент, доцент кафедры «Международная профессиональная и научная коммуникация»; Пономарев С.В., доктор технических наук, профессор, профессор кафедры «Мехатроника и технологические измерения» | U10: =VLOOKUP(A10,'БД направление'!$A:$H,8,0) -> Приборы, системы, изделия медицинского назначения | V10: Отлично | Y10: =CONCATENATE(V10,CHAR(10),W10,CHAR(10),X10," года") -> Отлично года | Z10: Фролов С.В., доктор технических наук, профессор, зав. кафедрой «Биомедицинская техника» | AA10: Проскурин С.Г., доктор технических наук, доцент, доцент кафедры «Биомедицинская техника», заместитель председателя комиссии | AB10: Дубровин В.В., кандидат технических наук, доцент, доцент кафедры «Биомедицинская техника» | AC10: =CONCATENATE(AA10,CHAR(10),AB10) -> Проскурин С.Г., доктор технических наук, доцент, доцент кафедры «Биомедицинская техника», заместитель председателя комиссии Дубровин В.В., кандидат технических наук, доцент, доцент кафедры «Биомедицинская техника»
